<?xml version="1.0" ?>
<sdf version="1.5">
  <model name="basic_mobile_bot">  
  <static>false</static>

  <!-- ****************** ROBOT BASE FOOTPRINT ***************************  -->
  <pose>0.0 0.0 0.0 0.0 0.0 0.0</pose>
  <link name="base_footprint"/>

  <!-- ********************** ROBOT BASE *********************************  -->
  <link name="base_link">

    <collision name="base_collision">
      <pose>0 0 0.1 0 0 0</pose>
      <geometry>
        <box>
          <size>0.70 0.39 0.20</size>
        </box>
      </geometry>
    </collision>

    <visual name="base_visual">
      <pose>0 0 -0.05 1.5707963267949 0 3.141592654</pose>
      <geometry>
        <mesh>
          <uri>model://basic_mobile_bot_description/meshes/robot_base.stl</uri>
          <scale>1.0 1.0 1.0</scale>
        </mesh>
      </geometry>
      <material>
        <ambient>1.0 0.0 0.0 1.0</ambient>
        <diffuse>1.0 0.0 0.0 1.0</diffuse>
        <specular>0.0 0.0 0.0 1.0</specular>
        <emissive>0.0 0.0 0.0 1.0</emissive>
      </material>
    </visual>
  </link>

  <!-- *********************** IMU SENSOR SETUP **************************  -->
  <link name="imu_link">
    <gravity>true</gravity>
    <sensor name="bmb_imu" type="imu">
      <always_on>true</always_on>
      <update_rate>100</update_rate>
      <visualize>true</visualize>
      <imu>
        <orientation>
          <x>
            <noise type="gaussian">
              <mean>0.0</mean>
              <stddev>2e-3</stddev>
            </noise>
          </x>
          <y>
            <noise type="gaussian">
              <mean>0.0</mean>
              <stddev>2e-3</stddev>
            </noise>
          </y>
          <z>
            <noise type="gaussian">
              <mean>0.0</mean>
              <stddev>2e-3</stddev>
            </noise>
          </z>
        </orientation>
        <angular_velocity>
          <x>
            <noise type="gaussian">
              <mean>0.0</mean>
              <stddev>2e-4</stddev>
            </noise>
          </x>
          <y>
            <noise type="gaussian">
              <mean>0.0</mean>
              <stddev>2e-4</stddev>
            </noise>
          </y>
          <z>
            <noise type="gaussian">
              <mean>0.0</mean>
              <stddev>2e-4</stddev>
            </noise>
          </z>
        </angular_velocity>
        <linear_acceleration>
          <x>
            <noise type="gaussian">
              <mean>0.0</mean>
              <stddev>1.7e-2</stddev>
            </noise>
          </x>
          <y>
            <noise type="gaussian">
              <mean>0.0</mean>
              <stddev>1.7e-2</stddev>
            </noise>
          </y>
          <z>
            <noise type="gaussian">
              <mean>0.0</mean>
              <stddev>1.7e-2</stddev>
            </noise>
          </z>
        </linear_acceleration>
      </imu>
      <plugin name="basic_mobile_bot_imu" filename="libgazebo_ros_imu_sensor.so">
        <initial_orientation_as_reference>false</initial_orientation_as_reference>
        <frame_name>imu_link</frame_name>
        <ros>
          <namespace>/imu</namespace>
          <remapping>~/out:=data</remapping>
        </ros>
      </plugin>
    </sensor>
  </link>

  <!-- *********************** GPS SETUP *********************************  -->
  <link name="gps_link">
    <sensor name="bmb_gps" type="gps">
      <always_on>true</always_on>
      <update_rate>10.0</update_rate>
      <gps>
        <position_sensing>
          <horizontal>
            <noise type="gaussian">
              <mean>0.0</mean>
              <stddev>1e-2</stddev>
            </noise>
          </horizontal>
          <vertical>
            <noise type="gaussian">
              <mean>0.0</mean>
              <stddev>1</stddev>
            </noise>
          </vertical>
        </position_sensing>
      </gps>
      <plugin name="basic_mobile_bot_gps" filename="libgazebo_ros_gps_sensor.so">
        <ros>
          <remapping>~/out:=gps/fix</remapping>
        </ros>
      </plugin>
    </sensor>
  </link>

  <!-- ****************************** LIDAR *****************************    -->
  <link name="lidar_link">    
    <inertial>
      <pose>0.215 0 0.8 0 0 0</pose>
      <inertia>
        <ixx>0.001</ixx>
        <ixy>0.000</ixy>
        <ixz>0.000</ixz>
        <iyy>0.001</iyy>
        <iyz>0.000</iyz>
        <izz>0.001</izz>
      </inertia>
      <mass>0.114</mass>
    </inertial>

    <collision name="lidar_collision">
      <pose>0.215 0 0.13 0 0 0</pose>
      <geometry>
        <cylinder>
          <radius>0.0508</radius>
          <length>0.18</length>
        </cylinder>
      </geometry>
    </collision>

    <visual name="lidar_visual">
      <pose>0.215 0 0.13 0 0 0</pose>
      <geometry>
        <cylinder>
          <radius>0.0508</radius>
          <length>0.18</length>
        </cylinder>
      </geometry>
      <material>
        <ambient>0.0 0.0 0.0 1.0</ambient>
        <diffuse>0.0 0.0 0.0 1.0</diffuse>
        <specular>0.0 0.0 0.0 1.0</specular>
        <emissive>0.0 0.0 0.0 1.0</emissive>
      </material>
    </visual>

    <sensor name="lidar" type="ray">
      <pose>0.215 0 0.215 0 0 0</pose>
      <always_on>true</always_on>
      <visualize>true</visualize>
      <update_rate>5</update_rate>
      <ray>
        <scan>
          <horizontal>
            <samples>120</samples>
            <resolution>1.000000</resolution>
            <min_angle>0</min_angle>
            <max_angle>6.283185</max_angle>
          </horizontal>
        </scan>
        <range>
          <min>0.12</min>
          <max>3.5</max>
          <resolution>0.015</resolution>
        </range>
        <noise>
          <type>gaussian</type>
          <mean>0.0</mean>
          <stddev>0.01</stddev>
        </noise>
      </ray>
      <plugin name="scan" filename="libgazebo_ros_ray_sensor.so">
        <ros>
          <remapping>~/out:=scan</remapping>
        </ros>
        <output_type>sensor_msgs/LaserScan</output_type>
        <frame_name>lidar_link</frame_name>
      </plugin>
    </sensor>
  </link>
  
  <!-- *********************** DRIVE WHEELS ******************************  -->
  <link name="rear_axle_link">
    <pose>-0.221 0 -0.05 0 1.570796 1.570796</pose>
  </link>

  <link name="drivewhl_l_link">
    <pose>-0.221 0.23 -0.05 0 1.570796 1.570796</pose>
    
    <collision name="drivewhl_l_collision">
      <geometry>
        <cylinder>
          <radius>0.14</radius>
          <length>0.06</length>
        </cylinder>
      </geometry>
    </collision>

    <visual name="drivewhl_l_visual">
      <geometry>
        <cylinder>
          <radius>0.14</radius>
          <length>0.06</length>
        </cylinder>
      </geometry>
    </visual>
  </link>

  <link name="drivewhl_r_link">
    <pose>-0.221 -0.23 -0.05 0 1.570796 1.570796</pose>
    
    <collision name="drivewhl_r_collision">
      <geometry>
        <cylinder>
          <radius>0.14</radius>
          <length>0.06</length>
        </cylinder>
      </geometry>
    </collision>

    <visual name="drivewhl_r_visual">
      <geometry>
        <cylinder>
          <radius>0.14</radius>
          <length>0.06</length>
        </cylinder>
      </geometry>
    </visual>
  </link>
 
  <!-- *********************** STEERING WHEEL ******************************  -->
  <!-- dummy link created to keep ackermann happy -->
  <link name="steering_wheel_link">
    <pose>0.217 0 -0.05 0 1.570796 1.570796</pose>
  </link>
  
  <link name="left_steering_link">
    <pose>0.217 0.1 -0.05 0 1.570796 1.570796</pose>
  </link>

  <link name="left_steering_wheel_link">
    <pose>0.217 0.1 -0.05 0 1.570796 1.570796</pose>
    <geometry>
      <cylinder>
        <radius>0.14</radius>
        <length>0.06</length>
      </cylinder>
    </geometry>
  </link>
  
  <link name="front_left_steering_wheel_link">
    <pose>0.217 0.1 -0.05 0 1.570796 1.570796</pose>
    
    <collision name="front_left_steering_wheel_collision">
      <geometry>
        <cylinder>
          <radius>0.14</radius>
          <length>0.06</length>
        </cylinder>
      </geometry>
    </collision>

    <visual name="front_left_steering_wheel_visual">
      <geometry>
        <cylinder>
          <radius>0.14</radius>
          <length>0.06</length>
        </cylinder>
      </geometry>
    </visual>
  </link>

 <link name="right_steering_link">
    <pose>0.217 -0.1 -0.05 0 1.570796 1.570796</pose>
  </link>

  <link name="right_steering_wheel_link">
    <pose>0.217 -0.1 -0.05 0 1.570796 1.570796</pose>
    <geometry>
      <cylinder>
        <radius>0.14</radius>
        <length>0.06</length>
      </cylinder>
    </geometry>
  </link>
  
  <link name="front_right_steering_wheel_link">
    <pose>0.217 -0.1 -0.05 0 1.570796 1.570796</pose>
    
    <collision name="front_right_steering_wheel_collision">
      <geometry>
        <cylinder>
          <radius>0.14</radius>
          <length>0.06</length>
        </cylinder>
      </geometry>
    </collision>

    <visual name="front_right_steering_wheel_visual">
      <geometry>
        <cylinder>
          <radius>0.14</radius>
          <length>0.06</length>
        </cylinder>
      </geometry>
    </visual>
  </link>

  <!-- ************************ JOINTS ***********************************  -->
  <!-- Pose of the joint is the same as the child link frame -->
  <!-- Axis is the axis of rotation relative to the child link frame -->
  
  <joint name="base_joint" type="fixed">
    <parent>base_footprint</parent>
    <child>base_link</child>
    <pose>0 0 0 0 0 0</pose>
  </joint>

  <joint name="rear_axle_joint" type="fixed">
   <parent>base_link</parent>
   <child>rear_axle_link</child>
   <pose>0 0 0 0 0 0</pose>
  </joint>

  <joint name="drivewhl_l_joint" type="revolute">
    <parent>rear_axle_link</parent>
    <child>drivewhl_l_link</child>
    <pose>0 0 0 0 0 0</pose>
    <axis>
      <xyz>0 0 1</xyz>
    </axis>
  </joint>

  <joint name="drivewhl_r_joint" type="revolute">
    <parent>rear_axle_link</parent>
    <child>drivewhl_r_link</child>
    <pose>0 0 0 0 0 0</pose>
    <axis>
      <xyz>0 0 1</xyz>
    </axis>
  </joint>
 
  <joint name="left_steering_joint" type="fixed">
   <parent>base_link</parent>
   <child>left_steering_link</child>
   <pose>0 0 0 0 0 0</pose>
  </joint>
 
  <!-- Dummy joint created to keep ackermann happy -->
  <joint name="steering_wheel_joint" type="revolute">
   <parent>base_link</parent>
   <child>steering_wheel_link</child>
   <pose>0 0 0 0 0 0</pose>
   <axis>
     <xyz>1 0 0</xyz>
   </axis>
  </joint>

  <joint name="left_steering_wheel_joint" type="revolute">
   <parent>left_steering_link</parent>
   <child>left_steering_wheel_link</child>
   <pose>0 0 0 0 0 0</pose>
   <axis>
     <xyz>-1 0 0</xyz>
   </axis>
  </joint>
	  
  <joint name="front_left_steering_wheel_joint" type="revolute">
   <parent>left_steering_wheel_link</parent>
   <child>front_left_steering_wheel_link</child>
   <pose>0 0 0 0 0 0</pose>
   <axis>
     <xyz>0 0 1</xyz>
   </axis>
  </joint>

  <joint name="right_steering_joint" type="fixed">
   <parent>base_link</parent>
   <child>right_steering_link</child>
   <pose>0 0 0 0 0 0</pose>
  </joint>

  <joint name="right_steering_wheel_joint" type="revolute">
   <parent>right_steering_link</parent>
   <child>right_steering_wheel_link</child>
   <pose>0 0 0 0 0 0</pose>
   <axis>
     <xyz>-1 0 0</xyz>
   </axis>
  </joint>
	  
  <joint name="front_right_steering_wheel_joint" type="revolute">
   <parent>right_steering_wheel_link</parent>
   <child>front_right_steering_wheel_link</child>
   <pose>0 0 0 0 0 0</pose>
   <axis>
     <xyz>0 0 1</xyz>
   </axis>
  </joint>

  <joint name="imu_joint" type="fixed">
   <parent>base_link</parent>
   <child>imu_link</child>
   <pose>0 0 0 0 0 0</pose>
  </joint>  

  <joint name="gps_joint" type="fixed">
    <parent>base_link</parent>
    <child>gps_link</child>
    <pose>0 0 0 0 0 0</pose>
  </joint>  
  
  <joint name="lidar_joint" type="fixed">
    <parent>base_link</parent>
    <child>lidar_link</child>
    <pose>0 0 0 0 0 0</pose>
  </joint>

  <!-- *********************** WHEEL ODOMETRY ***************************    -->
  <plugin name="dummy_plugin" filename="libgazebo_ros_hello_world_model_plugin.so"/>
  <plugin name="gazebo_ros_ackermann_drive_debug" filename="libgazebo_ros_ackermann_drive_debug.so">
    <ros>
      <namespace></namespace>
      <remapping>cmd_vel:=cmd_vel</remapping>
      <remapping>odom:=wheel/odometry</remapping>
      <!-- remapping>distance:=distance_demo</remapping -->
      <!-- this is to turn off publishing to tf when enabling ekf
      because we want transforms to now be updated by ekf node
      the plugin had no elegant config parameter to achieve this
      When not doing ekf, need to comment this out-->
      <!-- remapping>tf:=kachra</remapping -->
    </ros>

    <rear_left_joint>drivewhl_l_joint</rear_left_joint>
    <rear_right_joint>drivewhl_r_joint</rear_right_joint>
    <left_steering_joint>right_steering_wheel_joint</left_steering_joint>
    <right_steering_joint>left_steering_wheel_joint</right_steering_joint>
    <steering_wheel_joint>steering_wheel_joint</steering_wheel_joint>
    <front_right_joint>front_right_steering_wheel_joint</front_right_joint>
    <front_left_joint>front_left_steering_wheel_joint</front_left_joint>

    <update_rate>100.0</update_rate>

    <!-- Max absolute steer angle for tyre in radians-->
    <!-- Any cmd_vel angular z greater than this would be capped -->
    <max_steer>0.6458</max_steer>
  
    <!-- Max absolute steering angle of steering wheel -->
    <max_steering_angle>7.85</max_steering_angle>
  
    <!-- Max absolute linear speed in m/s -->
    <max_speed>20</max_speed>
  
    <!-- PID tuning -->
    <left_steering_pid_gain>1500 0 1</left_steering_pid_gain>
    <left_steering_i_range>0 0</left_steering_i_range>
    <right_steering_pid_gain>1500 0 1</right_steering_pid_gain>
    <right_steering_i_range>0 0</right_steering_i_range>
    <linear_velocity_pid_gain>1000 0 1</linear_velocity_pid_gain>
    <linear_velocity_i_range>0 0</linear_velocity_i_range>
  
    <!-- output -->
    <publish_odom>true</publish_odom>
    <publish_odom_tf>false</publish_odom_tf>
    <publish_wheel_tf>false</publish_wheel_tf>
    <publish_distance>true</publish_distance>
  
    <odometry_frame>odom</odometry_frame>
    <robot_base_frame>base_footprint</robot_base_frame>

    <!-- just imitated the params of tricycle plugin. not sure if the following two params exist in this plugin -->
    <!-- odometry_topic>odom</odometry_topic -->
    <!-- odometry_source>0</odometry_source -->     
  </plugin> 


 <!-- *********************** JOINT STATE PUBLISHER *********************   -->
  
  <plugin name="basic_mobile_bot_joint_state" filename="libgazebo_ros_joint_state_publisher.so">
    <ros>
      <remapping>~/out:=joint_states</remapping>
    </ros>
    <update_rate>30</update_rate>
    <joint_name>rear_axle_joint</joint_name>
    <joint_name>drivewhl_l_joint</joint_name>
    <joint_name>drivewhl_r_joint</joint_name>
    <joint_name>left_steering_joint</joint_name>
    <joint_name>left_steering_wheel_joint</joint_name>
    <joint_name>front_left_steering_wheel_joint</joint_name>
    <joint_name>right_steering_joint</joint_name>
    <joint_name>right_steering_wheel_joint</joint_name>
    <joint_name>front_right_steering_wheel_joint</joint_name>
    <joint_name>steering_wheel_joint</joint_name>
  </plugin>   
  
  </model>
</sdf>
